<?xml version="1.0" ?>
<!-- =================================================================================== -->
<!-- |    This document was autogenerated by xacro from r1d1_m.xacro                   | -->
<!-- |    EDITING THIS FILE BY HAND IS NOT RECOMMENDED                                 | -->
<!-- =================================================================================== -->
<robot name="robot">
  <material name="silver">
    <color rgba="0.700 0.700 0.700 1.000"/>
  </material>
  <transmission name="left_wheel_joint_tran">
    <type>transmission_interface/SimpleTransmission</type>
    <joint name="left_wheel_joint">
      <hardwareInterface>hardware_interface/EffortJointInterface</hardwareInterface>
    </joint>
    <actuator name="left_wheel_joint_actr">
      <hardwareInterface>hardware_interface/EffortJointInterface</hardwareInterface>
      <mechanicalReduction>1</mechanicalReduction>
    </actuator>
  </transmission>
  <transmission name="right_wheel_joint_tran">
    <type>transmission_interface/SimpleTransmission</type>
    <joint name="right_wheel_joint">
      <hardwareInterface>hardware_interface/EffortJointInterface</hardwareInterface>
    </joint>
    <actuator name="right_wheel_joint_actr">
      <hardwareInterface>hardware_interface/EffortJointInterface</hardwareInterface>
      <mechanicalReduction>1</mechanicalReduction>
    </actuator>
  </transmission>
  <transmission name="Slider 29_tran">
    <type>transmission_interface/SimpleTransmission</type>
    <joint name="Slider 29">
      <hardwareInterface>hardware_interface/EffortJointInterface</hardwareInterface>
    </joint>
    <actuator name="Slider 29_actr">
      <hardwareInterface>hardware_interface/EffortJointInterface</hardwareInterface>
      <mechanicalReduction>1</mechanicalReduction>
    </actuator>
  </transmission>
  <transmission name="Slider 30_tran">
    <type>transmission_interface/SimpleTransmission</type>
    <joint name="Slider 30">
      <hardwareInterface>hardware_interface/EffortJointInterface</hardwareInterface>
    </joint>
    <actuator name="Slider 30_actr">
      <hardwareInterface>hardware_interface/EffortJointInterface</hardwareInterface>
      <mechanicalReduction>1</mechanicalReduction>
    </actuator>
  </transmission>
  <transmission name="Slider 33_tran">
    <type>transmission_interface/SimpleTransmission</type>
    <joint name="Slider 33">
      <hardwareInterface>hardware_interface/EffortJointInterface</hardwareInterface>
    </joint>
    <actuator name="Slider 33_actr">
      <hardwareInterface>hardware_interface/EffortJointInterface</hardwareInterface>
      <mechanicalReduction>1</mechanicalReduction>
    </actuator>
  </transmission>
  <transmission name="Revolute 35_tran">
    <type>transmission_interface/SimpleTransmission</type>
    <joint name="Revolute 35">
      <hardwareInterface>hardware_interface/EffortJointInterface</hardwareInterface>
    </joint>
    <actuator name="Revolute 35_actr">
      <hardwareInterface>hardware_interface/EffortJointInterface</hardwareInterface>
      <mechanicalReduction>1</mechanicalReduction>
    </actuator>
  </transmission>
  <transmission name="Revolute 38_tran">
    <type>transmission_interface/SimpleTransmission</type>
    <joint name="Revolute 38">
      <hardwareInterface>hardware_interface/EffortJointInterface</hardwareInterface>
    </joint>
    <actuator name="Revolute 38_actr">
      <hardwareInterface>hardware_interface/EffortJointInterface</hardwareInterface>
      <mechanicalReduction>1</mechanicalReduction>
    </actuator>
  </transmission>
  <transmission name="Revolute 39_tran">
    <type>transmission_interface/SimpleTransmission</type>
    <joint name="Revolute 39">
      <hardwareInterface>hardware_interface/EffortJointInterface</hardwareInterface>
    </joint>
    <actuator name="Revolute 39_actr">
      <hardwareInterface>hardware_interface/EffortJointInterface</hardwareInterface>
      <mechanicalReduction>1</mechanicalReduction>
    </actuator>
  </transmission>
  <transmission name="Revolute 40_tran">
    <type>transmission_interface/SimpleTransmission</type>
    <joint name="Revolute 40">
      <hardwareInterface>hardware_interface/EffortJointInterface</hardwareInterface>
    </joint>
    <actuator name="Revolute 40_actr">
      <hardwareInterface>hardware_interface/EffortJointInterface</hardwareInterface>
      <mechanicalReduction>1</mechanicalReduction>
    </actuator>
  </transmission>
  <transmission name="Revolute 41_tran">
    <type>transmission_interface/SimpleTransmission</type>
    <joint name="Revolute 41">
      <hardwareInterface>hardware_interface/EffortJointInterface</hardwareInterface>
    </joint>
    <actuator name="Revolute 41_actr">
      <hardwareInterface>hardware_interface/EffortJointInterface</hardwareInterface>
      <mechanicalReduction>1</mechanicalReduction>
    </actuator>
  </transmission>
  <transmission name="Revolute 42_tran">
    <type>transmission_interface/SimpleTransmission</type>
    <joint name="Revolute 42">
      <hardwareInterface>hardware_interface/EffortJointInterface</hardwareInterface>
    </joint>
    <actuator name="Revolute 42_actr">
      <hardwareInterface>hardware_interface/EffortJointInterface</hardwareInterface>
      <mechanicalReduction>1</mechanicalReduction>
    </actuator>
  </transmission>
  <ros2_control name="GazeboSystem" type="system">
    <hardware>
      <plugin>gazebo_ros2_control/GazeboSystem</plugin>
    </hardware>
  </ros2_control>
  <gazebo reference="base_link">
    <material>Gazebo/Silver</material>
    <mu1>0.2</mu1>
    <mu2>0.2</mu2>
    <self_collide>true</self_collide>
    <gravity>true</gravity>
  </gazebo>
  <gazebo reference="left_wheel_1">
    <material>Gazebo/Silver</material>
    <mu1>0.2</mu1>
    <mu2>0.2</mu2>
    <self_collide>true</self_collide>
  </gazebo>
  <gazebo reference="right_wheel_1">
    <material>Gazebo/Silver</material>
    <mu1>0.2</mu1>
    <mu2>0.2</mu2>
    <self_collide>true</self_collide>
  </gazebo>
  <gazebo reference="caster_1_1">
    <material>Gazebo/Silver</material>
    <mu1>0.2</mu1>
    <mu2>0.2</mu2>
    <self_collide>true</self_collide>
  </gazebo>
  <gazebo reference="mount_v1_1">
    <material>Gazebo/Silver</material>
    <mu1>0.2</mu1>
    <mu2>0.2</mu2>
    <self_collide>true</self_collide>
  </gazebo>
  <gazebo reference="vertical_v1_1">
    <material>Gazebo/Silver</material>
    <mu1>0.2</mu1>
    <mu2>0.2</mu2>
    <self_collide>true</self_collide>
  </gazebo>
  <gazebo reference="gripper_finger_1">
    <material>Gazebo/Silver</material>
    <mu1>0.2</mu1>
    <mu2>0.2</mu2>
    <self_collide>true</self_collide>
  </gazebo>
  <gazebo reference="gripper_finger2_1">
    <material>Gazebo/Silver</material>
    <mu1>0.2</mu1>
    <mu2>0.2</mu2>
    <self_collide>true</self_collide>
  </gazebo>
  <gazebo reference="screen_v1_1">
    <material>Gazebo/Silver</material>
    <mu1>0.2</mu1>
    <mu2>0.2</mu2>
    <self_collide>true</self_collide>
  </gazebo>
  <gazebo reference="slider_1">
    <material>Gazebo/Silver</material>
    <mu1>0.2</mu1>
    <mu2>0.2</mu2>
    <self_collide>true</self_collide>
  </gazebo>
  <gazebo reference="arm_c1_1">
    <material>Gazebo/Silver</material>
    <mu1>0.2</mu1>
    <mu2>0.2</mu2>
    <self_collide>true</self_collide>
  </gazebo>
  <gazebo reference="amr_c2_1">
    <material>Gazebo/Silver</material>
    <mu1>0.2</mu1>
    <mu2>0.2</mu2>
    <self_collide>true</self_collide>
  </gazebo>
  <gazebo reference="arm_c4_1">
    <material>Gazebo/Silver</material>
    <mu1>0.2</mu1>
    <mu2>0.2</mu2>
    <self_collide>true</self_collide>
  </gazebo>
  <gazebo reference="arm_c5_1">
    <material>Gazebo/Silver</material>
    <mu1>0.2</mu1>
    <mu2>0.2</mu2>
    <self_collide>true</self_collide>
  </gazebo>
  <gazebo reference="arm_c6_1">
    <material>Gazebo/Silver</material>
    <mu1>0.2</mu1>
    <mu2>0.2</mu2>
    <self_collide>true</self_collide>
  </gazebo>
  <gazebo reference="amr_c3_1">
    <material>Gazebo/Silver</material>
    <mu1>0.2</mu1>
    <mu2>0.2</mu2>
    <self_collide>true</self_collide>
  </gazebo>
  <gazebo reference="arm_c7_1">
    <material>Gazebo/Silver</material>
    <mu1>0.2</mu1>
    <mu2>0.2</mu2>
    <self_collide>true</self_collide>
  </gazebo>
  <gazebo reference="gripper_base_1">
    <material>Gazebo/Silver</material>
    <mu1>0.2</mu1>
    <mu2>0.2</mu2>
    <self_collide>true</self_collide>
  </gazebo>
  <gazebo reference="camera_1">
    <material>Gazebo/Silver</material>
    <mu1>0.2</mu1>
    <mu2>0.2</mu2>
    <self_collide>true</self_collide>
  </gazebo>
  <gazebo reference="lidar_1">
    <material>Gazebo/Silver</material>
    <mu1>0.2</mu1>
    <mu2>0.2</mu2>
    <self_collide>true</self_collide>
  </gazebo>
  <joint name="Rigid 45" type="revolute">
    <origin rpy="0 0 0" xyz="0.0 -0.117 0.0525"/>
    <parent link="screen_v1_1"/>
    <child link="camera_1"/>
    <axis xyz="0 0 1"/>
    <limit effort="0" lower="0" upper="0" velocity="0"/>
  </joint>
  <link name="camera_1">
    <inertial>
      <origin rpy="0 0 0" xyz="6.1791840987637954e-15 -0.01000010951681022 -7.127631818093505e-14"/>
      <mass value="0.05166258768470149"/>
      <inertia ixx="3e-06" ixy="-0.0" ixz="-0.0" iyy="1.9e-05" iyz="0.0" izz="1.9e-05"/>
    </inertial>
    <visual>
      <origin rpy="0 0 0" xyz="-0.0 0.031999 -1.8375"/>
      <geometry>
        <mesh filename="file:///home/ishan/OpenDroids_ws/install/r1d1_description/share/r1d1_description/meshes/camera_1.stl" scale="0.001 0.001 0.001"/>
      </geometry>
      <material name="silver"/>
    </visual>
    <collision>
      <origin rpy="0 0 0" xyz="-0.0 0.031999 -1.8375"/>
      <geometry>
        <mesh filename="file:///home/ishan/OpenDroids_ws/install/r1d1_description/share/r1d1_description/meshes/camera_1.stl" scale="0.001 0.001 0.001"/>
      </geometry>
    </collision>
  </link>
  <gazebo reference="camera_1">
    <sensor name="rgbd_camera" type="rgbd_camera">
      <!--The pose here is a bit random so need to be adjusted-->
      <pose>-0.0 -1.0 1.5 0 0 -1.5708</pose>
      <camera>
        <horizontal_fov>1.2</horizontal_fov>
        <image>
          <width>640</width>
          <height>480</height>
          <format>BAYER_RGGB8</format>
        </image>
        <clip>
          <near>0.02</near>
          <far>10</far>
        </clip>
      </camera>
      <always_on>1</always_on>
      <!--If running at good RTF then lower the update rate to 30 or so-->
      <update_rate>10000</update_rate>
      <visualize>true</visualize>
      <topic>rgbd_camera</topic>
      <plugin filename="ignition-gazebo-sensors-system" name="gz::sim::systems::Sensors">
        <render_engine>ogre2</render_engine>
      </plugin>
    </sensor>
  </gazebo>
  <link name="base_link">
    <inertial>
      <origin rpy="0 0 0" xyz="1.1547257273897802e-06 -0.007635347278315616 0.15138662427903304"/>
      <mass value="36.898914712235424"/>
      <inertia ixx="0.87793" ixy="2.9e-05" ixz="9e-06" iyy="0.993842" iyz="-0.00262" izz="1.325469"/>
    </inertial>
    <visual>
      <origin rpy="0 0 0" xyz="0 0 0"/>
      <geometry>
        <mesh filename="file:///home/ishan/OpenDroids_ws/install/r1d1_description/share/r1d1_description/meshes/base_link.stl" scale="0.001 0.001 0.001"/>
      </geometry>
      <material name="silver"/>
    </visual>
    <collision>
      <origin rpy="0 0 0" xyz="0 0 0"/>
      <geometry>
        <mesh filename="file:///home/ishan/OpenDroids_ws/install/r1d1_description/share/r1d1_description/meshes/base_link.stl" scale="0.001 0.001 0.001"/>
      </geometry>
    </collision>
  </link>
  <link name="left_wheel_1">
    <inertial>
      <origin rpy="0 0 0" xyz="0.03933261352596262 -3.102141997377017e-07 3.896188927043909e-15"/>
      <mass value="1.2020197871482743"/>
      <inertia ixx="0.003741" ixy="-0.0" ixz="0.0" iyy="0.002176" iyz="0.0" izz="0.002176"/>
    </inertial>
    <visual>
      <origin rpy="0 0 0" xyz="-0.125905 -0.011214 -0.01"/>
      <geometry>
        <mesh filename="file:///home/ishan/OpenDroids_ws/install/r1d1_description/share/r1d1_description/meshes/left_wheel_1.stl" scale="0.001 0.001 0.001"/>
      </geometry>
      <material name="silver"/>
    </visual>
    <collision>
      <origin rpy="0 0 0" xyz="-0.125905 -0.011214 -0.01"/>
      <geometry>
        <mesh filename="file:///home/ishan/OpenDroids_ws/install/r1d1_description/share/r1d1_description/meshes/left_wheel_1.stl" scale="0.001 0.001 0.001"/>
      </geometry>
    </collision>
  </link>
  <link name="right_wheel_1">
    <inertial>
      <origin rpy="0 0 0" xyz="-0.03933261352596262 1.2614637535327683e-06 3.896188927043909e-15"/>
      <mass value="1.2020197871482743"/>
      <inertia ixx="0.003741" ixy="-0.0" ixz="-0.0" iyy="0.002176" iyz="-0.0" izz="0.002176"/>
    </inertial>
    <visual>
      <origin rpy="0 0 0" xyz="0.125905 -0.011214 -0.01"/>
      <geometry>
        <mesh filename="file:///home/ishan/OpenDroids_ws/install/r1d1_description/share/r1d1_description/meshes/right_wheel_1.stl" scale="0.001 0.001 0.001"/>
      </geometry>
      <material name="silver"/>
    </visual>
    <collision>
      <origin rpy="0 0 0" xyz="0.125905 -0.011214 -0.01"/>
      <geometry>
        <mesh filename="file:///home/ishan/OpenDroids_ws/install/r1d1_description/share/r1d1_description/meshes/right_wheel_1.stl" scale="0.001 0.001 0.001"/>
      </geometry>
    </collision>
  </link>
  <link name="caster_1_1">
    <inertial>
      <origin rpy="0 0 0" xyz="0.0749999955448851 0.17500002391840322 -0.037229533269406326"/>
      <mass value="0.18492935556768103"/>
      <inertia ixx="0.000111" ixy="0.0" ixz="0.0" iyy="9.7e-05" iyz="-0.0" izz="8.2e-05"/>
    </inertial>
    <visual>
      <origin rpy="0 0 0" xyz="-0.0 -0.0 -0.0"/>
      <geometry>
        <mesh filename="file:///home/ishan/OpenDroids_ws/install/r1d1_description/share/r1d1_description/meshes/caster_1_1.stl" scale="0.001 0.001 0.001"/>
      </geometry>
      <material name="silver"/>
    </visual>
    <collision>
      <origin rpy="0 0 0" xyz="-0.0 -0.0 -0.0"/>
      <geometry>
        <mesh filename="file:///home/ishan/OpenDroids_ws/install/r1d1_description/share/r1d1_description/meshes/caster_1_1.stl" scale="0.001 0.001 0.001"/>
      </geometry>
    </collision>
  </link>
  <link name="mount_v1_1">
    <inertial>
      <origin rpy="0 0 0" xyz="0.004699834778461813 0.06797243215558421 0.5691408369250166"/>
      <mass value="37.46152841680288"/>
      <inertia ixx="7.91068" ixy="0.009948" ixz="-0.022667" iyy="8.256966" iyz="-0.366828" izz="0.734564"/>
    </inertial>
    <visual>
      <origin rpy="0 0 0" xyz="-0.0 -0.0 -0.28"/>
      <geometry>
        <mesh filename="file:///home/ishan/OpenDroids_ws/install/r1d1_description/share/r1d1_description/meshes/mount_v1_1.stl" scale="0.001 0.001 0.001"/>
      </geometry>
      <material name="silver"/>
    </visual>
    <collision>
      <origin rpy="0 0 0" xyz="-0.0 -0.0 -0.28"/>
      <geometry>
        <mesh filename="file:///home/ishan/OpenDroids_ws/install/r1d1_description/share/r1d1_description/meshes/mount_v1_1.stl" scale="0.001 0.001 0.001"/>
      </geometry>
    </collision>
  </link>
  <link name="vertical_v1_1">
    <inertial>
      <origin rpy="0 0 0" xyz="0.300276 -0.16840510951680002 -1.74076100000007"/>
      <mass value="24.32699999999999"/>
      <inertia ixx="4.577733" ixy="-0.0" ixz="-0.0" iyy="4.6199" iyz="0.0" izz="0.075008"/>
    </inertial>
    <visual>
      <origin rpy="0 0 0" xyz="0.300276 -0.208406 -2.775761"/>
      <geometry>
        <mesh filename="file:///home/ishan/OpenDroids_ws/install/r1d1_description/share/r1d1_description/meshes/vertical_v1_1.stl" scale="0.001 0.001 0.001"/>
      </geometry>
      <material name="silver"/>
    </visual>
    <collision>
      <origin rpy="0 0 0" xyz="0.300276 -0.208406 -2.775761"/>
      <geometry>
        <mesh filename="file:///home/ishan/OpenDroids_ws/install/r1d1_description/share/r1d1_description/meshes/vertical_v1_1.stl" scale="0.001 0.001 0.001"/>
      </geometry>
    </collision>
  </link>
  <link name="gripper_finger_1">
    <inertial>
      <origin rpy="0 0 0" xyz="-1.2887005800870863 -0.07296498486252255 0.3041595690014297"/>
      <mass value="0.016384204166531253"/>
      <inertia ixx="7e-06" ixy="-0.0" ixz="4e-06" iyy="1e-05" iyz="0.0" izz="5e-06"/>
    </inertial>
    <visual>
      <origin rpy="0 0 0" xyz="-2.00986 0.095929 -0.899244"/>
      <geometry>
        <mesh filename="file:///home/ishan/OpenDroids_ws/install/r1d1_description/share/r1d1_description/meshes/gripper_finger_1.stl" scale="0.001 0.001 0.001"/>
      </geometry>
      <material name="silver"/>
    </visual>
    <collision>
      <origin rpy="0 0 0" xyz="-2.00986 0.095929 -0.899244"/>
      <geometry>
        <mesh filename="file:///home/ishan/OpenDroids_ws/install/r1d1_description/share/r1d1_description/meshes/gripper_finger_1.stl" scale="0.001 0.001 0.001"/>
      </geometry>
    </collision>
  </link>
  <link name="gripper_finger2_1">
    <inertial>
      <origin rpy="0 0 0" xyz="-1.3007475016955818 -0.06995542399105785 0.2920686540778593"/>
      <mass value="0.016384204166531253"/>
      <inertia ixx="5e-06" ixy="0.0" ixz="4e-06" iyy="1e-05" iyz="-0.0" izz="7e-06"/>
    </inertial>
    <visual>
      <origin rpy="0 0 0" xyz="-2.00986 0.095929 -0.899244"/>
      <geometry>
        <mesh filename="file:///home/ishan/OpenDroids_ws/install/r1d1_description/share/r1d1_description/meshes/gripper_finger2_1.stl" scale="0.001 0.001 0.001"/>
      </geometry>
      <material name="silver"/>
    </visual>
    <collision>
      <origin rpy="0 0 0" xyz="-2.00986 0.095929 -0.899244"/>
      <geometry>
        <mesh filename="file:///home/ishan/OpenDroids_ws/install/r1d1_description/share/r1d1_description/meshes/gripper_finger2_1.stl" scale="0.001 0.001 0.001"/>
      </geometry>
    </collision>
  </link>
  <link name="screen_v1_1">
    <inertial>
      <origin rpy="0 0 0" xyz="1.84011819724741e-11 -0.03889295266081586 0.11598843171162043"/>
      <mass value="1.3238858059375562"/>
      <inertia ixx="0.00685" ixy="0.0" ixz="0.0" iyy="0.008161" iyz="0.001577" izz="0.003561"/>
    </inertial>
    <visual>
      <origin rpy="0 0 0" xyz="-0.0 -0.085001 -1.785"/>
      <geometry>
        <mesh filename="file:///home/ishan/OpenDroids_ws/install/r1d1_description/share/r1d1_description/meshes/screen_v1_1.stl" scale="0.001 0.001 0.001"/>
      </geometry>
      <material name="silver"/>
    </visual>
    <collision>
      <origin rpy="0 0 0" xyz="-0.0 -0.085001 -1.785"/>
      <geometry>
        <mesh filename="file:///home/ishan/OpenDroids_ws/install/r1d1_description/share/r1d1_description/meshes/screen_v1_1.stl" scale="0.001 0.001 0.001"/>
      </geometry>
    </collision>
  </link>
  <link name="slider_1">
    <inertial>
      <origin rpy="0 0 0" xyz="-5.902504556725109e-18 -0.002500109516799993 -6.994405055138486e-14"/>
      <mass value="0.43604999999999994"/>
      <inertia ixx="0.001313" ixy="0.0" ixz="-0.0" iyy="0.002362" iyz="0.0" izz="0.001051"/>
    </inertial>
    <visual>
      <origin rpy="0 0 0" xyz="0.0 0.004999 -1.035"/>
      <geometry>
        <mesh filename="file:///home/ishan/OpenDroids_ws/install/r1d1_description/share/r1d1_description/meshes/slider_1.stl" scale="0.001 0.001 0.001"/>
      </geometry>
      <material name="silver"/>
    </visual>
    <collision>
      <origin rpy="0 0 0" xyz="0.0 0.004999 -1.035"/>
      <geometry>
        <mesh filename="file:///home/ishan/OpenDroids_ws/install/r1d1_description/share/r1d1_description/meshes/slider_1.stl" scale="0.001 0.001 0.001"/>
      </geometry>
    </collision>
  </link>
  <link name="arm_c1_1">
    <inertial>
      <origin rpy="0 0 0" xyz="-2.78263793284472e-05 -0.032527409110111094 -0.0006654684875286865"/>
      <mass value="0.3077654114507175"/>
      <inertia ixx="0.000539" ixy="0.0" ixz="0.0" iyy="0.000776" iyz="6e-06" izz="0.000548"/>
    </inertial>
    <visual>
      <origin rpy="0 0 0" xyz="0.0 0.009999 -1.035"/>
      <geometry>
        <mesh filename="file:///home/ishan/OpenDroids_ws/install/r1d1_description/share/r1d1_description/meshes/arm_c1_1.stl" scale="0.001 0.001 0.001"/>
      </geometry>
      <material name="silver"/>
    </visual>
    <collision>
      <origin rpy="0 0 0" xyz="0.0 0.009999 -1.035"/>
      <geometry>
        <mesh filename="file:///home/ishan/OpenDroids_ws/install/r1d1_description/share/r1d1_description/meshes/arm_c1_1.stl" scale="0.001 0.001 0.001"/>
      </geometry>
    </collision>
  </link>
  <link name="amr_c2_1">
    <inertial>
      <origin rpy="0 0 0" xyz="0.0017122003101182226 -0.05521343954562406 -0.0017056690936951835"/>
      <mass value="0.8336850329541245"/>
      <inertia ixx="0.001385" ixy="9e-06" ixz="1.6e-05" iyy="0.000909" iyz="-9e-06" izz="0.001385"/>
    </inertial>
    <visual>
      <origin rpy="0 0 0" xyz="-0.0 0.089799 -1.035"/>
      <geometry>
        <mesh filename="file:///home/ishan/OpenDroids_ws/install/r1d1_description/share/r1d1_description/meshes/amr_c2_1.stl" scale="0.001 0.001 0.001"/>
      </geometry>
      <material name="silver"/>
    </visual>
    <collision>
      <origin rpy="0 0 0" xyz="-0.0 0.089799 -1.035"/>
      <geometry>
        <mesh filename="file:///home/ishan/OpenDroids_ws/install/r1d1_description/share/r1d1_description/meshes/amr_c2_1.stl" scale="0.001 0.001 0.001"/>
      </geometry>
    </collision>
  </link>
  <link name="arm_c4_1">
    <inertial>
      <origin rpy="0 0 0" xyz="0.055635248736101484 -3.323298905510974e-08 0.12568017736494497"/>
      <mass value="1.9148915468217087"/>
      <inertia ixx="0.010371" ixy="-0.0" ixz="-0.007787" iyy="0.017911" iyz="-0.0" izz="0.00916"/>
    </inertial>
    <visual>
      <origin rpy="0 0 0" xyz="-0.23574 0.149799 -1.195377"/>
      <geometry>
        <mesh filename="file:///home/ishan/OpenDroids_ws/install/r1d1_description/share/r1d1_description/meshes/arm_c4_1.stl" scale="0.001 0.001 0.001"/>
      </geometry>
      <material name="silver"/>
    </visual>
    <collision>
      <origin rpy="0 0 0" xyz="-0.23574 0.149799 -1.195377"/>
      <geometry>
        <mesh filename="file:///home/ishan/OpenDroids_ws/install/r1d1_description/share/r1d1_description/meshes/arm_c4_1.stl" scale="0.001 0.001 0.001"/>
      </geometry>
    </collision>
  </link>
  <link name="arm_c5_1">
    <inertial>
      <origin rpy="0 0 0" xyz="0.027931367316718747 0.001141639371120412 -0.03694297864771845"/>
      <mass value="0.7917902286710067"/>
      <inertia ixx="0.000962" ixy="6.1e-05" ixz="-0.00023" iyy="0.001203" iyz="6.5e-05" izz="0.00093"/>
    </inertial>
    <visual>
      <origin rpy="0 0 0" xyz="-0.404577 0.149799 -1.365964"/>
      <geometry>
        <mesh filename="file:///home/ishan/OpenDroids_ws/install/r1d1_description/share/r1d1_description/meshes/arm_c5_1.stl" scale="0.001 0.001 0.001"/>
      </geometry>
      <material name="silver"/>
    </visual>
    <collision>
      <origin rpy="0 0 0" xyz="-0.404577 0.149799 -1.365964"/>
      <geometry>
        <mesh filename="file:///home/ishan/OpenDroids_ws/install/r1d1_description/share/r1d1_description/meshes/arm_c5_1.stl" scale="0.001 0.001 0.001"/>
      </geometry>
    </collision>
  </link>
  <link name="arm_c6_1">
    <inertial>
      <origin rpy="0 0 0" xyz="0.03182669751725131 -0.007873936279006344 0.03129187486567342"/>
      <mass value="0.6685877298515001"/>
      <inertia ixx="0.00076" ixy="5e-06" ixz="0.000157" iyy="0.000958" iyz="5e-06" izz="0.000763"/>
    </inertial>
    <visual>
      <origin rpy="0 0 0" xyz="-0.475637 0.158915 -1.368144"/>
      <geometry>
        <mesh filename="file:///home/ishan/OpenDroids_ws/install/r1d1_description/share/r1d1_description/meshes/arm_c6_1.stl" scale="0.001 0.001 0.001"/>
      </geometry>
      <material name="silver"/>
    </visual>
    <collision>
      <origin rpy="0 0 0" xyz="-0.475637 0.158915 -1.368144"/>
      <geometry>
        <mesh filename="file:///home/ishan/OpenDroids_ws/install/r1d1_description/share/r1d1_description/meshes/arm_c6_1.stl" scale="0.001 0.001 0.001"/>
      </geometry>
    </collision>
  </link>
  <link name="amr_c3_1">
    <inertial>
      <origin rpy="0 0 0" xyz="0.13969122062090347 -8.388348304855242e-08 0.05844792124625198"/>
      <mass value="2.940490372828695"/>
      <inertia ixx="0.021212" ixy="0.0" ixz="-0.01706" iyy="0.039248" iyz="0.0" izz="0.021088"/>
    </inertial>
    <visual>
      <origin rpy="0 0 0" xyz="-0.038112 0.149799 -0.997027"/>
      <geometry>
        <mesh filename="file:///home/ishan/OpenDroids_ws/install/r1d1_description/share/r1d1_description/meshes/amr_c3_1.stl" scale="0.001 0.001 0.001"/>
      </geometry>
      <material name="silver"/>
    </visual>
    <collision>
      <origin rpy="0 0 0" xyz="-0.038112 0.149799 -0.997027"/>
      <geometry>
        <mesh filename="file:///home/ishan/OpenDroids_ws/install/r1d1_description/share/r1d1_description/meshes/amr_c3_1.stl" scale="0.001 0.001 0.001"/>
      </geometry>
    </collision>
  </link>
  <link name="arm_c7_1">
    <inertial>
      <origin rpy="0 0 0" xyz="0.013946843385206464 3.245700232556992e-05 -0.01379788517027336"/>
      <mass value="0.21151566499231975"/>
      <inertia ixx="0.00014" ixy="-0.0" ixz="-2.7e-05" iyy="0.000113" iyz="-0.0" izz="0.00014"/>
    </inertial>
    <visual>
      <origin rpy="0 0 0" xyz="-0.549936 0.167389 -1.361957"/>
      <geometry>
        <mesh filename="file:///home/ishan/OpenDroids_ws/install/r1d1_description/share/r1d1_description/meshes/arm_c7_1.stl" scale="0.001 0.001 0.001"/>
      </geometry>
      <material name="silver"/>
    </visual>
    <collision>
      <origin rpy="0 0 0" xyz="-0.549936 0.167389 -1.361957"/>
      <geometry>
        <mesh filename="file:///home/ishan/OpenDroids_ws/install/r1d1_description/share/r1d1_description/meshes/arm_c7_1.stl" scale="0.001 0.001 0.001"/>
      </geometry>
    </collision>
  </link>
  <link name="gripper_base_1">
    <inertial>
      <origin rpy="0 0 0" xyz="0.050859725463711425 -2.1799271313072133e-07 -0.0506748564046926"/>
      <mass value="0.7474580686995151"/>
      <inertia ixx="0.001142" ixy="4.3e-05" ixz="0.000429" iyy="0.00191" iyz="4.4e-05" izz="0.001145"/>
    </inertial>
    <visual>
      <origin rpy="0 0 0" xyz="-0.580397 0.167389 -1.331607"/>
      <geometry>
        <mesh filename="file:///home/ishan/OpenDroids_ws/install/r1d1_description/share/r1d1_description/meshes/gripper_base_1.stl" scale="0.001 0.001 0.001"/>
      </geometry>
      <material name="silver"/>
    </visual>
    <collision>
      <origin rpy="0 0 0" xyz="-0.580397 0.167389 -1.331607"/>
      <geometry>
        <mesh filename="file:///home/ishan/OpenDroids_ws/install/r1d1_description/share/r1d1_description/meshes/gripper_base_1.stl" scale="0.001 0.001 0.001"/>
      </geometry>
    </collision>
  </link>
  <link name="lidar_1">
    <inertial>
      <origin rpy="0 0 0" xyz="-3.8657673471382324e-17 -4.13193513695842e-07 0.015000000000000013"/>
      <mass value="0.6616194128460102"/>
      <inertia ixx="0.00048" ixy="0.0" ixz="0.0" iyy="0.00048" iyz="-0.0" izz="0.00086"/>
    </inertial>
    <visual>
      <origin rpy="0 0 0" xyz="0.0 0.123483 -0.155"/>
      <geometry>
        <mesh filename="file:///home/ishan/OpenDroids_ws/install/r1d1_description/share/r1d1_description/meshes/lidar_1.stl" scale="0.001 0.001 0.001"/>
      </geometry>
      <material name="silver"/>
    </visual>
    <collision>
      <origin rpy="0 0 0" xyz="0.0 0.123483 -0.155"/>
      <geometry>
        <mesh filename="file:///home/ishan/OpenDroids_ws/install/r1d1_description/share/r1d1_description/meshes/lidar_1.stl" scale="0.001 0.001 0.001"/>
      </geometry>
    </collision>
  </link>
  <joint name="left_wheel_joint" type="continuous">
    <origin rpy="0 0 0" xyz="0.125905 0.011214 0.01"/>
    <parent link="base_link"/>
    <child link="left_wheel_1"/>
    <axis xyz="-1.0 0.0 0.0"/>
  </joint>
  <joint name="right_wheel_joint" type="continuous">
    <origin rpy="0 0 0" xyz="-0.125905 0.011214 0.01"/>
    <parent link="base_link"/>
    <child link="right_wheel_1"/>
    <axis xyz="1.0 -0.0 0.0"/>
  </joint>
  <joint name="Rigid 7" type="fixed">
    <origin rpy="0 0 0" xyz="0.0 0.0 0.0"/>
    <parent link="base_link"/>
    <child link="caster_1_1"/>
  </joint>
  <joint name="Rigid 21" type="fixed">
    <origin rpy="0 0 0" xyz="0.0 0.0 0.28"/>
    <parent link="base_link"/>
    <child link="mount_v1_1"/>
  </joint>
  <joint name="Rigid 23" type="fixed">
    <origin rpy="0 0 0" xyz="-0.300276 0.208406 2.495761"/>
    <parent link="mount_v1_1"/>
    <child link="vertical_v1_1"/>
  </joint>
  <joint name="Slider 29" type="prismatic">
    <origin rpy="0 0 0" xyz="1.429463 0.07146 -0.432363"/>
    <parent link="gripper_base_1"/>
    <child link="gripper_finger_1"/>
    <axis xyz="0.695094 -0.173648 0.697632"/>
    <limit effort="100" lower="0.0055" upper="0.045" velocity="100"/>
  </joint>
  <joint name="Slider 30" type="prismatic">
    <origin rpy="0 0 0" xyz="1.429463 0.07146 -0.432363"/>
    <parent link="gripper_base_1"/>
    <child link="gripper_finger2_1"/>
    <axis xyz="0.695094 -0.173648 0.697632"/>
    <limit effort="100" lower="-0.04" upper="-0.0005" velocity="100"/>
  </joint>
  <joint name="Rigid 31" type="fixed">
    <origin rpy="0 0 0" xyz="0.300276 -0.123405 -0.990761"/>
    <parent link="vertical_v1_1"/>
    <child link="screen_v1_1"/>
  </joint>
  <joint name="Slider 33" type="prismatic">
    <origin rpy="0 0 0" xyz="0.300276 -0.213405 -1.740761"/>
    <parent link="vertical_v1_1"/>
    <child link="slider_1"/>
    <axis xyz="0.0 -0.0 1.0"/>
    <limit effort="100" lower="-0.64" upper="0.64" velocity="100"/>
  </joint>
  <joint name="Rigid 34" type="fixed">
    <origin rpy="0 0 0" xyz="0.0 -0.005 0.0"/>
    <parent link="slider_1"/>
    <child link="arm_c1_1"/>
  </joint>
  <joint name="Revolute 35" type="continuous">
    <origin rpy="0 0 0" xyz="0.0 -0.0798 0.0"/>
    <parent link="arm_c1_1"/>
    <child link="amr_c2_1"/>
    <axis xyz="0.0 -1.0 -0.0"/>
  </joint>
  <joint name="Revolute 38" type="continuous">
    <origin rpy="0 0 0" xyz="0.197628 0.0 0.19835"/>
    <parent link="amr_c3_1"/>
    <child link="arm_c4_1"/>
    <axis xyz="0.708394 0.0 -0.705817"/>
  </joint>
  <joint name="Revolute 39" type="continuous">
    <origin rpy="0 0 0" xyz="0.168837 0.0 0.170587"/>
    <parent link="arm_c4_1"/>
    <child link="arm_c5_1"/>
    <axis xyz="-0.708394 -0.0 0.705817"/>
  </joint>
  <joint name="Revolute 40" type="continuous">
    <origin rpy="0 0 0" xyz="0.07106 -0.009116 0.00218"/>
    <parent link="arm_c5_1"/>
    <child link="arm_c6_1"/>
    <axis xyz="-0.695094 0.173648 -0.697632"/>
  </joint>
  <joint name="Revolute 41" type="continuous">
    <origin rpy="0 0 0" xyz="0.038112 -0.06 -0.037973"/>
    <parent link="amr_c2_1"/>
    <child link="amr_c3_1"/>
    <axis xyz="0.708394 0.0 -0.705817"/>
  </joint>
  <joint name="Revolute 42" type="continuous">
    <origin rpy="0 0 0" xyz="0.074299 -0.008474 -0.006187"/>
    <parent link="arm_c6_1"/>
    <child link="arm_c7_1"/>
    <axis xyz="0.708394 0.0 -0.705817"/>
  </joint>
  <joint name="Rigid 43" type="fixed">
    <origin rpy="0 0 0" xyz="0.030461 0.0 -0.03035"/>
    <parent link="arm_c7_1"/>
    <child link="gripper_base_1"/>
  </joint>
  <joint name="Rigid 46" type="fixed">
    <origin rpy="0 0 0" xyz="0.0 -0.123483 0.155"/>
    <parent link="base_link"/>
    <child link="lidar_1"/>
  </joint>
  <ros2_control name="GazeboSystem" type="system">
    <hardware>
      <plugin>ign_ros2_control/IgnitionSystem</plugin>
    </hardware>
    <joint name="Slider 33">
      <command_interface name="position"/>
      <state_interface name="position">
        <param name="initial_value">0.3</param>
      </state_interface>
      <state_interface name="velocity"/>
    </joint>
    <joint name="Revolute 35">
      <command_interface name="position">
            </command_interface>
      <state_interface name="position">
        <param name="initial_value">1.48</param>
      </state_interface>
      <state_interface name="velocity"/>
      <state_interface name="effort"/>
    </joint>
    <joint name="Revolute 41">
      <command_interface name="position">
            </command_interface>
      <state_interface name="position">
        <param name="initial_value">0.5</param>
      </state_interface>
      <state_interface name="velocity"/>
      <state_interface name="effort"/>
    </joint>
    <joint name="Revolute 38">
      <command_interface name="position">
            </command_interface>
      <state_interface name="position">
        <param name="initial_value">2.182</param>
      </state_interface>
      <state_interface name="velocity"/>
      <state_interface name="effort"/>
    </joint>
    <joint name="Revolute 39">
      <command_interface name="position">
            </command_interface>
      <state_interface name="position">
        <param name="initial_value">5.6</param>
      </state_interface>
      <state_interface name="velocity"/>
      <state_interface name="effort"/>
    </joint>
    <joint name="Revolute 40">
      <command_interface name="position">
            </command_interface>
      <state_interface name="position">
        <param name="initial_value">0.55</param>
      </state_interface>
      <state_interface name="velocity"/>
      <state_interface name="effort"/>
    </joint>
    <joint name="Revolute 42">
      <command_interface name="position">
            </command_interface>
      <state_interface name="position">
        <param name="initial_value">1.8</param>
      </state_interface>
      <state_interface name="velocity"/>
      <state_interface name="effort"/>
    </joint>
    <joint name="Slider 29">
      <command_interface name="position"/>
      <state_interface name="position">
        <param name="initial_value">0.0081</param>
      </state_interface>
      <state_interface name="velocity"/>
    </joint>
    <joint name="Slider 30">
      <command_interface name="position"/>
      <state_interface name="position">
        <param name="initial_value">-0.0040</param>
      </state_interface>
      <state_interface name="velocity"/>
    </joint>
    <joint name="left_wheel_joint">
      <command_interface name="velocity">
        <param name="min">-10</param>
        <param name="max">10</param>
      </command_interface>
      <state_interface name="position"/>
      <state_interface name="velocity"/>
    </joint>
    <joint name="right_wheel_joint">
      <command_interface name="velocity">
        <param name="min">-10</param>
        <param name="max">10</param>
      </command_interface>
      <state_interface name="velocity"/>
      <state_interface name="position"/>
    </joint>
  </ros2_control>
  <gazebo>
    <plugin filename="ign_ros2_control-system" name="ign_ros2_control::IgnitionROS2ControlPlugin">
      <parameters>/home/ishan/OpenDroids_ws/install/r1d1_description/share/r1d1_description/config/r1d1.yaml</parameters>
    </plugin>
  </gazebo>
  <!-- <xacro:include filename="$(find r1d1_description)/urdf/gazebo_control.xacro" />     -->
  <!-- <xacro:include filename="$(find r1d1_description)/urdf/lidar.xacro" /> -->
  <!-- <xacro:include filename="camera.xacro" /> -->
  <!-- <xacro:include filename="depth_camera.xacro" /> -->
  <!-- <xacro:include filename="face.xacro" /> -->
</robot>
